<?xml version="1.0"?>
<robot xmlns:xacro="http://www.ros.org/wiki/xacro">
  <xacro:include filename="$(find scorpio_description)/urdf/sensors/hokuyo_utm30lx.urdf.xacro" />
  <xacro:include filename="$(find scorpio_description)/urdf/base/base.gazebo.xacro" />
  <xacro:include filename="$(find scorpio_description)/urdf/base/base.transmission.xacro" />

  <xacro:property name="pi" value="3.1415926535897931" />
  <xacro:property name="wheel_w" value="0.05" />
  <xacro:property name="passive_wheel_rad" value="0.0375" />
  <xacro:property name="active_wheel_rad" value="0.1" />

  <xacro:property name="psvwheel_mass" value="0.010" />
  <xacro:property name="actvwheel_mass" value="0.020" />

  <!-- Inertia calculating -->
  <xacro:macro name="cuboid_inertial" params="width height depth mass *origin">
    <inertial>
      <mass value="${mass}" />
      <xacro:insert_block name="origin" />
      <inertia ixx="${0.0833333 * mass * (depth * depth + height * height)}" ixy="0.0" ixz="0.0"
        iyy="${0.0833333 * mass * ( width * width + depth * depth)}" iyz="0.0"
        izz="${0.0833333 * mass * ( width * width + height * height)}" />
    </inertial>
  </xacro:macro>

  <!--left and right active wheel-->
  <xacro:macro name="rl_wheel" params="prefix reflect">
    <link name="${prefix}_wheel">
      <visual>
        <geometry>
          <cylinder length="${wheel_w}" radius="${active_wheel_rad}"/>
        </geometry>
        <origin rpy="${pi/2} 0 0" xyz="0 0 0"/>
        <material name="black"/>
      </visual>
      <collision>
        <geometry>
          <cylinder length="${wheel_w}" radius="${active_wheel_rad}"/>
        </geometry>
        <origin rpy="${pi/2} 0 0" xyz="0 0 0"/>
      </collision>
      <inertial>
        <mass value="0.010" />
        <origin rpy="${pi/2} 0 0" xyz="0 0 0" />
        <inertia
          ixx="${(1/12) * actvwheel_mass * (3 * active_wheel_rad * active_wheel_rad + wheel_w * wheel_w)}" ixy="0.0" ixz="0.0"
          iyy="${(1/12) * actvwheel_mass * (3 * active_wheel_rad * active_wheel_rad + wheel_w * wheel_w)}" iyz="0.0"
          izz="${0.5 * actvwheel_mass * active_wheel_rad * active_wheel_rad }" />
      </inertial>
    </link>
    <joint name="${prefix}_wheel_joint" type="continuous">
      <origin
        xyz="0.0 ${reflect * -0.218} -0.146"
        rpy="0 0 0" />
      <parent link="base_link" />
      <child link="${prefix}_wheel"/>
      <axis xyz="0 1 0" />
    </joint>

    <!-- extensions -->
    <xacro:scorpio_rl_wheel_gazebo prefix="${prefix}"/>
    <xacro:scorpio_wheel_transmission prefix="${prefix}"/>
  </xacro:macro>

  <!--front and back passive wheel-->
  <xacro:macro name="fb_wheel" params="prefix reflect">
    <link name="${prefix}_right_wheel">
      <inertial>
        <mass value="0.010" />
        <origin rpy="${pi/2} 0 0" xyz="0 0 0" />
        <inertia
          ixx="${(1/12) * psvwheel_mass * (3 * passive_wheel_rad * passive_wheel_rad + wheel_w * wheel_w)}" ixy="0.0" ixz="0.0"
          iyy="${(1/12) * psvwheel_mass * (3 * passive_wheel_rad * passive_wheel_rad + wheel_w * wheel_w)}" iyz="0.0"
          izz="${0.5 * psvwheel_mass * passive_wheel_rad * passive_wheel_rad }" />
      </inertial>
      <visual>
        <geometry>
          <cylinder length="${wheel_w}" radius="${passive_wheel_rad}"/>
        </geometry>
        <origin rpy="${pi/2} 0 0" xyz="0 0 0"/>
        <material name="blue"/>
      </visual>
      <collision>
        <geometry>
          <cylinder length="${wheel_w}" radius="${passive_wheel_rad}"/>
        </geometry>
        <origin rpy="${pi/2} 0 0" xyz="0 0 0"/>
      </collision>
    </link>
    <joint name="${prefix}_right_wheel_joint" type="fixed">
      <origin
        xyz="${reflect * 0.50975} -0.26714 -0.2085"
        rpy="0 0 0" />
      <parent link="base_link" />
      <child link="${prefix}_right_wheel"/>
      <axis xyz="0 0 0" />
    </joint>

    <link name="${prefix}_left_wheel">
      <visual>
        <geometry>
          <cylinder length="${wheel_w}" radius="${passive_wheel_rad}"/>
        </geometry>
        <origin rpy="${pi/2} 0 0" xyz="0 0 0"/>
        <material name="blue"/>
      </visual>
      <collision>
        <geometry>
          <cylinder length="${wheel_w}" radius="${passive_wheel_rad}"/>
        </geometry>
        <origin rpy="${pi/2} 0 0" xyz="0 0 0"/>
      </collision>
      <inertial>
        <mass value="0.010" />
        <origin rpy="${pi/2} 0 0" xyz="0 0 0" />
        <inertia
          ixx="${(1/12) * psvwheel_mass * (3 * passive_wheel_rad * passive_wheel_rad + wheel_w * wheel_w)}" ixy="0.0" ixz="0.0"
          iyy="${(1/12) * psvwheel_mass * (3 * passive_wheel_rad * passive_wheel_rad + wheel_w * wheel_w)}" iyz="0.0"
          izz="${0.5 * psvwheel_mass * passive_wheel_rad * passive_wheel_rad }" />
      </inertial>
    </link>
    <joint name="${prefix}_left_wheel_joint" type="fixed">
      <origin
        xyz="${reflect * 0.50975} 0.26714 -0.2085"
        rpy="0 0 0" />
      <parent link="base_link" />
      <child link="${prefix}_left_wheel"/>
      <axis xyz="0 0 0" />
    </joint>

    <!-- extensions -->
    <xacro:scorpio_fb_wheel_gazebo prefix="${prefix}"/>
  </xacro:macro>

  <xacro:macro name="scorpio_base" params="ns">
    <link name="base_footprint"/>

    <joint name="base_footprint_joint" type="fixed">
      <origin xyz="0 0 0.246" rpy="0 0 0" />
      <child link="base_link" />
      <parent link="base_footprint"/>
    </joint>

    <link name="base_link">
      <xacro:cuboid_inertial width="1.2" height="0.9" depth="0.5" mass="20">
        <origin xyz="0.0 0.0 0" rpy="0 0 0" />
      </xacro:cuboid_inertial>
      <visual>
        <origin xyz="0 0 0" rpy="0 0 0" />
        <geometry>
          <mesh filename="package://scorpio_description/meshes/base_link.STL" />
        </geometry>
        <material name="">
          <color rgba="0.792156862745098 0.819607843137255 0.933333333333333 1" />
        </material>
      </visual>
      <collision>
        <origin xyz="0 0 0" rpy="0 0 0" />
        <geometry>
          <mesh filename="package://scorpio_description/meshes/base_link.STL" />
          <!--box size="1.0 0.56 0.42"/-->
        </geometry>
      </collision>
    </link>

    <!-- virtual laser -->
    <joint name="vlaser_joint" type="fixed">
      <axis xyz="0 0 0"/> <!-- 0 1 0 -->
      <origin xyz="0 0 0" rpy="0 0 0"/>
      <parent link="base_link"/>
      <child link="vlaser_link"/>
    </joint>
    <link name="vlaser_link"/>

    <!-- Sparkfun imu-->
    <joint name="imu_joint" type="fixed">
      <axis xyz="0 0 0"/> <!-- 0 1 0 -->
      <origin xyz="0 0 0" rpy="0 0 0"/>
      <parent link="base_footprint"/>
      <child link="base_imu_link"/>
    </joint>
    <link name="base_imu_link"/>
    <xacro:scorpio_imu_gazebo/>

    <!-- wheel macros-->
    <xacro:rl_wheel prefix="right" reflect="1"/>
    <xacro:rl_wheel prefix="left" reflect="-1"/>
    <xacro:fb_wheel prefix="front" reflect="1"/>
    <xacro:fb_wheel prefix="back" reflect="-1"/>

    <!-- Hokuyo utm30lx, total_x_differ=1.09 total_y_differ=0.677 -->
    <xacro:hokuyo_utm30lx name="front" parent="base_link">
      <origin xyz="0.535 0.3285 0" rpy="0 0 0.7235"/> <!--45 -3.x -->
    </xacro:hokuyo_utm30lx>
    <xacro:hokuyo_utm30lx name="back" parent="base_link"> <!--225 -2.5 -->
      <origin xyz="-0.555 -0.3485 0" rpy="0 0 3.8833576"/>
    </xacro:hokuyo_utm30lx>

    <!-- ASUS Xtion Pro -->
    <!--xacro:asus_xtion_pro name="base_camera" parent="base_link" ns="${ns}"/-->

    <!-- extensions -->
    <xacro:scorpio_base_gazebo/>

  </xacro:macro>
</robot>
